Workbook

Sheet Dashboard
B2: HR ANALYTICS DASHBOARD
B4: Employee Attrition & Workforce Analysis
B6: Total Employees | E6: Employees Left | H6: Attrition Rate | K6: Average Age | M6: Average Monthly Income
B7: ='AnalysisHR Analytics'!B4 -> 1470 | E7: ='AnalysisHR Analytics'!B5 -> 237 | H7: ='AnalysisHR Analytics'!B6 -> 0.16122449 | K7: ='AnalysisHR Analytics'!B7 -> 36.92381 | M7: ='AnalysisHR Analytics'!B8 -> 6502.9313
B11: Average Companies worked
B12: ='AnalysisHR Analytics'!B9 -> 2.6931973

Sheet Pivot Tables
A3: Count of attrition | B3: Column Labels | J3: Count of attrition | K3: Column Labels
A4: Row Labels | B4: No | C4: Yes | D4: Grand Total | F4: Row Labels | G4: Yes | J4: Row Labels | K4: No | L4: Yes | M4: Grand Total | O4: Row Labels | P4: Yes
A5: Human Resources | B5: 0.80952381 | C5: 0.19047619 | D5: 1 | F5: Human Resources | G5: 0.19047619 | J5: Bachelors | K5: 0.82692308 | L5: 0.17307692 | M5: 1 | O5: Bachelors | P5: 0.17307692
A6: Research & Development | B6: 0.8616025 | C6: 0.1383975 | D6: 1 | F6: Research & Development | G6: 0.1383975 | J6: Doctorate | K6: 0.89583333 | L6: 0.10416667 | M6: 1 | O6: Doctorate | P6: 0.10416667
A7: Sales | B7: 0.79372197 | C7: 0.20627803 | D7: 1 | F7: Sales | G7: 0.20627803 | J7: Masters | K7: 0.85427136 | L7: 0.14572864 | M7: 1 | O7: Masters | P7: 0.14572864
A8: Grand Total | B8: 0.83877551 | C8: 0.16122449 | D8: 1 | J8: No college | K8: 0.81764706 | L8: 0.18235294 | M8: 1 | O8: No college | P8: 0.18235294
J9: Some college | K9: 0.84397163 | L9: 0.15602837 | M9: 1 | O9: Some college | P9: 0.15602837
A10: Count of attrition | B10: Column Labels | J10: Grand Total | K10: 0.83877551 | L10: 0.16122449 | M10: 1
A11: Row Labels | B11: No | C11: Yes | D11: Grand Total | F11: Row Labels | G11: Yes
A12: Healthcare Representative | B12: 0.93129771 | C12: 0.06870229 | D12: 1 | F12: Healthcare Representative | G12: 0.06870229
A13: Human Resources | B13: 0.76923077 | C13: 0.23076923 | D13: 1 | F13: Human Resources | G13: 0.23076923
A14: Laboratory Technician | B14: 0.76061776 | C14: 0.23938224 | D14: 1 | F14: Laboratory Technician | G14: 0.23938224
A15: Manager | B15: 0.95098039 | C15: 0.049019608 | D15: 1 | F15: Manager | G15: 0.049019608
A16: Manufacturing Director | B16: 0.93103448 | C16: 0.068965517 | D16: 1 | F16: Manufacturing Director | G16: 0.068965517
A17: Research Director | B17: 0.975 | C17: 0.025 | D17: 1 | F17: Research Director | G17: 0.025
A18: Research Scientist | B18: 0.8390411 | C18: 0.1609589 | D18: 1 | F18: Research Scientist | G18: 0.1609589
A19: Sales Executive | B19: 0.82515337 | C19: 0.17484663 | D19: 1 | F19: Sales Executive | G19: 0.17484663
A20: Sales Representative | B20: 0.60240964 | C20: 0.39759036 | D20: 1 | F20: Sales Representative | G20: 0.39759036
A21: Grand Total | B21: 0.83877551 | C21: 0.16122449 | D21: 1
A23: Count of attrition | B23: Column Labels | F23: Row Labels | G23: Yes
A24: Row Labels | B24: No | C24: Yes | D24: Grand Total | F24: Female | G24: 0.14795918
A25: Female | B25: 0.85204082 | C25: 0.14795918 | D25: 1 | F25: Male | G25: 0.17006803
A26: Male | B26: 0.82993197 | C26: 0.17006803 | D26: 1
A27: Grand Total | B27: 0.83877551 | C27: 0.16122449 | D27: 1
A29: Count of attrition | B29: Column Labels
A30: Row Labels | B30: No | C30: Yes | D30: Grand Total | F30: Row Labels | G30: Yes
A31: No | B31: 0.89563567 | C31: 0.10436433 | D31: 1 | F31: No | G31: 0.10436433
A32: Yes | B32: 0.69471154 | C32: 0.30528846 | D32: 1 | F32: Yes | G32: 0.30528846
A33: Grand Total | B33: 0.83877551 | C33: 0.16122449 | D33: 1
A35: Count of attrition | B35: Column Labels | F35: Row Labels | G35: Yes
A36: Row Labels | B36: No | C36: Yes | D36: Grand Total | F36: High | G36: 0.16515837
A37: High | B37: 0.83484163 | C37: 0.16515837 | D37: 1 | F37: Low | G37: 0.2283737
A38: Low | B38: 0.7716263 | C38: 0.2283737 | D38: 1 | F38: Medium | G38: 0.16428571
A39: Medium | B39: 0.83571429 | C39: 0.16428571 | D39: 1 | F39: Very high | G39: 0.11328976
A40: Very high | B40: 0.88671024 | C40: 0.11328976 | D40: 1
A41: Grand Total | B41: 0.83877551 | C41: 0.16122449 | D41: 1
A43: Count of attrition | B43: Column Labels | F43: Row Labels | G43: Yes
A44: Row Labels | B44: No | C44: Yes | D44: Grand Total | F44: 25-34 | G44: 0.20216606
A45: 25-34 | B45: 0.79783394 | C45: 0.20216606 | D45: 1 | F45: 35-44 | G45: 0.1009901
A46: 35-44 | B46: 0.8990099 | C46: 0.1009901 | D46: 1 | F46: 45-54 | G46: 0.10204082
...

Sheet HR Data
A1: employee_number | B1: age | C1: attrition | D1: business_travel | E1: department | F1: distance_from_home | G1: education | H1: education_field | I1: environment_satisfaction | J1: gender | K1: job_involvement | L1: job_role | M1: job_satisfaction | N1: marital_status | O1: monthly_income | P1: num_companies_worked | Q1: over_time | R1: percent_salary_hike | S1: performance_rating | T1: relationship_satisfaction | U1: training_times_last_year | V1: work_life_balance | W1: Age_Group | X1: Income_Group
A2: 1 | B2: 41 | C2: Yes | D2: Travel_Rarely | E2: Sales | F2: 1 | G2: Some college | H2: Life Sciences | I2: Medium | J2: Female | K2: High | L2: Sales Executive | M2: Very high | N2: Single | O2: 5993 | P2: 8 | Q2: Yes | R2: 11 | S2: Excellent | T2: Low | U2: 0 | V2: Bad | W2: =IF(HR_Data[[#This Row],[age]]<25,"Under 25",IF(HR_Data[[#This Row],[age]]<35,"25-34",IF(HR_Data[[#This Row],[age]]<45,"35-44",IF(HR_Data[[#This Row],[age]]<55,"45-54","55+")))) -> 35-44 | X2: =IF(O2<3000,"Below 3,000",IF(O2<5000,"3,000-4,999",IF(O2<8000,"5,000-7,999","8,000+"))) -> 5,000-7,999
A3: 2 | B3: 49 | C3: No | D3: Travel_Frequently | E3: Research & Development | F3: 8 | G3: No college | H3: Life Sciences | I3: High | J3: Male | K3: Medium | L3: Research Scientist | M3: Medium | N3: Married | O3: 5130 | P3: 1 | Q3: No | R3: 23 | S3: Outstanding | T3: Very high | U3: 3 | V3: Better | W3: =IF(HR_Data[[#This Row],[age]]<25,"Under 25",IF(HR_Data[[#This Row],[age]]<35,"25-34",IF(HR_Data[[#This Row],[age]]<45,"35-44",IF(HR_Data[[#This Row],[age]]<55,"45-54","55+")))) -> 45-54 | X3: =IF(O3<3000,"Below 3,000",IF(O3<5000,"3,000-4,999",IF(O3<8000,"5,000-7,999","8,000+"))) -> 5,000-7,999
A4: 4 | B4: 37 | C4: Yes | D4: Travel_Rarely | E4: Research & Development | F4: 2 | G4: Some college | H4: Other | I4: Very high | J4: Male | K4: Medium | L4: Laboratory Technician | M4: High | N4: Single | O4: 2090 | P4: 6 | Q4: Yes | R4: 15 | S4: Excellent | T4: Medium | U4: 3 | V4: Better | W4: =IF(HR_Data[[#This Row],[age]]<25,"Under 25",IF(HR_Data[[#This Row],[age]]<35,"25-34",IF(HR_Data[[#This Row],[age]]<45,"35-44",IF(HR_Data[[#This Row],[age]]<55,"45-54","55+")))) -> 35-44 | X4: =IF(O4<3000,"Below 3,000",IF(O4<5000,"3,000-4,999",IF(O4<8000,"5,000-7,999","8,000+"))) -> Below 3,000
A5: 5 | B5: 33 | C5: No | D5: Travel_Frequently | E5: Research & Development | F5: 3 | G5: Masters | H5: Life Sciences | I5: Very high | J5: Female | K5: High | L5: Research Scientist | M5: High | N5: Married | O5: 2909 | P5: 1 | Q5: Yes | R5: 11 | S5: Excellent | T5: High | U5: 3 | V5: Better | W5: =IF(HR_Data[[#This Row],[age]]<25,"Under 25",IF(HR_Data[[#This Row],[age]]<35,"25-34",IF(HR_Data[[#This Row],[age]]<45,"35-44",IF(HR_Data[[#This Row],[age]]<55,"45-54","55+")))) -> 25-34 | X5: =IF(O5<3000,"Below 3,000",IF(O5<5000,"3,000-4,999",IF(O5<8000,"5,000-7,999","8,000+"))) -> Below 3,000
A6: 7 | B6: 27 | C6: No | D6: Travel_Rarely | E6: Research & Development | F6: 2 | G6: No college | H6: Medical | I6: Low | J6: Male | K6: High | L6: Laboratory Technician | M6: Medium | N6: Married | O6: 3468 | P6: 9 | Q6: No | R6: 12 | S6: Excellent | T6: Very high | U6: 3 | V6: Better | W6: =IF(HR_Data[[#This Row],[age]]<25,"Under 25",IF(HR_Data[[#This Row],[age]]<35,"25-34",IF(HR_Data[[#This Row],[age]]<45,"35-44",IF(HR_Data[[#This Row],[age]]<55,"45-54","55+")))) -> 25-34 | X6: =IF(O6<3000,"Below 3,000",IF(O6<5000,"3,000-4,999",IF(O6<8000,"5,000-7,999","8,000+"))) -> 3,000-4,999
A7: 8 | B7: 32 | C7: No | D7: Travel_Frequently | E7: Research & Development | F7: 2 | G7: Some college | H7: Life Sciences | I7: Very high | J7: Male | K7: High | L7: Laboratory Technician | M7: Very high | N7: Single | O7: 3068 | P7: 0 | Q7: No | R7: 13 | S7: Excellent | T7: High | U7: 2 | V7: Good | W7: =IF(HR_Data[[#This Row],[age]]<25,"Under 25",IF(HR_Data[[#This Row],[age]]<35,"25-34",IF(HR_Data[[#This Row],[age]]<45,"35-44",IF(HR_Data[[#This Row],[age]]<55,"45-54","55+")))) -> 25-34 | X7: =IF(O7<3000,"Below 3,000",IF(O7<5000,"3,000-4,999",IF(O7<8000,"5,000-7,999","8,000+"))) -> 3,000-4,999
A8: 10 | B8: 59 | C8: No | D8: Travel_Rarely | E8: Research & Development | F8: 3 | G8: Bachelors | H8: Medical | I8: High | J8: Female | K8: Very high | L8: Laboratory Technician | M8: Low | N8: Married | O8: 2670 | P8: 4 | Q8: Yes | R8: 20 | S8: Outstanding | T8: Low | U8: 3 | V8: Good | W8: =IF(HR_Data[[#This Row],[age]]<25,"Under 25",IF(HR_Data[[#This Row],[age]]<35,"25-34",IF(HR_Data[[#This Row],[age]]<45,"35-44",IF(HR_Data[[#This Row],[age]]<55,"45-54","55+")))) -> 55+ | X8: =IF(O8<3000,"Below 3,000",IF(O8<5000,"3,000-4,999",IF(O8<8000,"5,000-7,999","8,000+"))) -> Below 3,000
A9: 11 | B9: 30 | C9: No | D9: Travel_Rarely | E9: Research & Development | F9: 24 | G9: No college | H9: Life Sciences | I9: Very high | J9: Male | K9: High | L9: Laboratory Technician | M9: High | N9: Divorced | O9: 2693 | P9: 1 | Q9: No | R9: 22 | S9: Outstanding | T9: Medium | U9: 2 | V9: Better | W9: =IF(HR_Data[[#This Row],[age]]<25,"Under 25",IF(HR_Data[[#This Row],[age]]<35,"25-34",IF(HR_Data[[#This Row],[age]]<45,"35-44",IF(HR_Data[[#This Row],[age]]<55,"45-54","55+")))) -> 25-34 | X9: =IF(O9<3000,"Below 3,000",IF(O9<5000,"3,000-4,999",IF(O9<8000,"5,000-7,999","8,000+"))) -> Below 3,000
A10: 12 | B10: 38 | C10: No | D10: Travel_Frequently | E10: Research & Development | F10: 23 | G10: Bachelors | H10: Life Sciences | I10: Very high | J10: Male | K10: Medium | L10: Manufacturing Director | M10: High | N10: Single | O10: 9526 | P10: 0 | Q10: No | R10: 21 | S10: Outstanding | T10: Medium | U10: 2 | V10: Better | W10: =IF(HR_Data[[#This Row],[age]]<25,"Under 25",IF(HR_Data[[#This Row],[age]]<35,"25-34",IF(HR_Data[[#This Row],[age]]<45,"35-44",IF(HR_Data[[#This Row],[age]]<55,"45-54","55+")))) -> 35-44 | X10: =IF(O10<3000,"Below 3,000",IF(O10<5000,"3,000-4,999",IF(O10<8000,"5,000-7,999","8,000+"))) -> 8,000+
A11: 13 | B11: 36 | C11: No | D11: Travel_Rarely | E11: Research & Development | F11: 27 | G11: Bachelors | H11: Medical | I11: High | J11: Male | K11: High | L11: Healthcare Representative | M11: High | N11: Married | O11: 5237 | P11: 6 | Q11: No | R11: 13 | S11: Excellent | T11: Medium | U11: 3 | V11: Good | W11: =IF(HR_Data[[#This Row],[age]]<25,"Under 25",IF(HR_Data[[#This Row],[age]]<35,"25-34",IF(HR_Data[[#This Row],[age]]<45,"35-44",IF(HR_Data[[#This Row],[age]]<55,"45-54","55+")))) -> 35-44 | X11: =IF(O11<3000,"Below 3,000",IF(O11<5000,"3,000-4,999",IF(O11<8000,"5,000-7,999","8,000+"))) -> 5,000-7,999
A12: 14 | B12: 35 | C12: No | D12: Travel_Rarely | E12: Research & Development | F12: 16 | G12: Bachelors | H12: Medical | I12: Low | J12: Male | K12: Very high | L12: Laboratory Technician | M12: Medium | N12: Married | O12: 2426 | P12: 0 | Q12: No | R12: 13 | S12: Excellent | T12: High | U12: 5 | V12: Better | W12: =IF(HR_Data[[#This Row],[age]]<25,"Under 25",IF(HR_Data[[#This Row],[age]]<35,"25-34",IF(HR_Data[[#This Row],[age]]<45,"35-44",IF(HR_Data[[#This Row],[age]]<55,"45-54","55+")))) -> 35-44 | X12: =IF(O12<3000,"Below 3,000",IF(O12<5000,"3,000-4,999",IF(O12<8000,"5,000-7,999","8,000+"))) -> Below 3,000
A13: 15 | B13: 29 | C13: No | D13: Travel_Rarely | E13: Research & Development | F13: 15 | G13: Some college | H13: Life Sciences | I13: Very high | J13: Female | K13: Medium | L13: Laboratory Technician | M13: High | N13: Single | O13: 4193 | P13: 0 | Q13: Yes | R13: 12 | S13: Excellent | T13: Very high | U13: 3 | V13: Better | W13: =IF(HR_Data[[#This Row],[age]]<25,"Under 25",IF(HR_Data[[#This Row],[age]]<35,"25-34",IF(HR_Data[[#This Row],[age]]<45,"35-44",IF(HR_Data[[#This Row],[age]]<55,"45-54","55+")))) -> 25-34 | X13: =IF(O13<3000,"Below 3,000",IF(O13<5000,"3,000-4,999",IF(O13<8000,"5,000-7,999","8,000+"))) -> 3,000-4,999
... A1471: 2068 | B1471: 34 | C1471: No | D1471: Travel_Rarely | E1471: Research & Development | F1471: 8 | G1471: Bachelors | H1471: Medical | I1471: Medium | J1471: Male | K1471: Very high | L1471: Laboratory Technician | M1471: High | N1471: Married | O1471: 4404 | P1471: 2 | Q1471: No | R1471: 12 | S1471: Excellent | T1471: Low | U1471: 3 | V1471: Best | W1471: =IF(HR_Data[[#This Row],[age]]<25,"Under 25",IF(HR_Data[[#This Row],[age]]<35,"25-34",IF(HR_Data[[#This Row],[age]]<45,"35-44",IF(HR_Data[[#This Row],[age]]<55,"45-54","55+")))) -> 25-34 | X1471: =IF(O1471<3000,"Below 3,000",IF(O1471<5000,"3,000-4,999",IF(O1471<8000,"5,000-7,999","8,000+"))) -> 3,000-4,999

Sheet AnalysisHR Analytics
A1: HR Analytics-Key Performance Indicators
A3: KPI | B3: Value
A4: Total Employees | B4: =ROWS(HR_Data[age]) -> 1470
A5: Employees Left | B5: =COUNTIF(HR_Data[attrition],"Yes") -> 237
A6: Attrition Rate | B6: =B5/B4 -> 0.16122449
A7: Average Age | B7: =AVERAGE(HR_Data[age]) -> 36.92381
A8: Average Monthly Income | B8: =AVERAGE(HR_Data[monthly_income]) -> 6502.9313
A9: Average Companies Worked | B9: =AVERAGE(HR_Data[num_companies_worked]) -> 2.6931973
